Workbook

Sheet M&S
A1: CHANGE LIST | D1: Note lại ở cột này nha còn lại t lock hết r
A2: STT | B2: Current arguement | C2: Pending resolvement | D2: Suggested arguement | E2: Disapproved | F2: Why (Optional)
C3: =COUNTIF(C4:C253,"No") -> 3 | E3: =COUNTIF(E4:E253,"Denied") -> 0
A4: 1 | B4: Odd pricing - Standard: 6,790,000 ₫ - Advanced: 8,990,000 ₫ - E-bike: 17,990,000 ₫ | C4: YES | E4: FALSE
A5: 2 | B5: Giảm cho distributor 20% | C5: NO | E5: FALSE
A6: 3 | B6: 2 distributor chính - 200 chiếc/distri./month Các distributor, kênh bán hàng còn lại - 100 chiếc/month | C6: NO | E6: FALSE
A7: 4 | B7: Toàn bộ timeline plan marketing - Budget: chưa rõ - Projected sale: chưa có - Projected supply: chưa có | C7: NO | E7: FALSE
A8: 5 | C8: FALSE | E8: FALSE
A9: 6 | C9: FALSE | E9: FALSE
A10: 7 | C10: FALSE | E10: FALSE
A11: 8 | C11: FALSE | E11: FALSE
A12: 9 | C12: FALSE | E12: FALSE
A13: 10 | C13: FALSE | E13: FALSE
A14: 11 | C14: FALSE | E14: FALSE
A15: 12 | C15: FALSE | E15: FALSE
A16: 13 | C16: FALSE | E16: FALSE
A17: 14 | C17: FALSE | E17: FALSE
A18: 15 | C18: FALSE | E18: FALSE
A19: 16 | C19: FALSE | E19: FALSE
... A203: 200 | C203: FALSE | E203: FALSE

Sheet Parameter
A1: PARAMETER SHEET
A4: I/ Capital related
A6: WORKING CAPITAL
A7: Cash balance | B7: 0.1 | C7: Minimum | D7: Owner's investment
A8: Account receivable | B8: 0.5 | C8: On purchase | D8: Distributor
B9: 0.3 | C9: 1st period after purchase
B10: =1-B8-B9 -> 0.2 | C10: 2nd period after purchase
A11: Account payable | B11: 0.7 | C11: On purchase | D11: Inventory
B12: =1-B11 -> 0.3 | C12: 1st period after purchase
A13: Inventory | B13: 0.1 | C13: Minimum | D13: Production cap
B14: ='Operations plan'!C67 -> 0.12 | C14: Preproduce 1 month prior | D14: Store
B15: ='Operations plan'!C70 -> 0.12 | C15: Preproduce 1 month prior | D15: Distributors
A18: CAPITAL STRUCTURE
A19: Equity Funding | B19: Amount | C19: Corresponding percentage (%) | D19: Date received
A20: Owner Investment | B20: =SUM(B21:B24) -> 36000000000 | C20: 0.5
A21: Hoàng Anh Tú | B21: 7300000000 | C21: =B21/B$20 -> 0.20277778 | D21: 45657
A22: Nguyễn Phạm Gia Bảo | B22: 9400000000 | C22: =B22/B$20 -> 0.26111111 | D22: 45657
A23: Phạm Đình Khánh Băng | B23: 9700000000 | C23: =B23/B$20 -> 0.26944444 | D23: 45657
A24: Nguyễn Gia Khánh | B24: 9600000000 | C24: =B24/B$20 -> 0.26666667 | D24: 45657
A25: Bank loan | B25: =C25*$B$27 -> 1.44e+10 | C25: =1-(C20+C26) -> 0.2 | D25: 45780
A26: Angel investors | B26: =C26*$B$27 -> 21600000000 | C26: 0.3 | D26: 45700
A27: TOTAL | B27: =B20/C20 -> 72000000000
A30: REPAYMENT PLAN
A31: Loan | B31: =B25 -> 1.44e+10 | C31: Loan term | D31: 1 year
A32: Interest rate | B32: 0.0731 | C32: Repayment form | D32: Equal principle
A33: Renewal | B33: Annually | C33: Payment period | D33: Monthly
B34: 46022 | C34: 46387 | D34: 46752
A35: Loan balance | B35: =$B$31 -> 1.44e+10 | C35: =B39 -> 1.44e+10 | D35: =C39 -> 1.44e+10
A36: Repayments | B36: =SUM(B37:B38) -> #NAME? | C36: =SUM(C37:C38) -> #NAME? | D36: =SUM(D37:D38) -> #NAME?
A37: Paid interest | B37: {=SUM($B$31*(1-SEQUENCE(1,13,0)/12)*$B$32/12)} -> #NAME? | C37: {=SUM($B$31*(1-SEQUENCE(1,13,0)/12)*$B$32/12)} -> #NAME? | D37: {=SUM($B$31*(1-SEQUENCE(1,13,0)/12)*$B$32/12)} -> #NAME?
A38: Paid principal | B38: =B35/12*(DATEDIF(D25,DATEVALUE("12-31-2025"),"M")) -> #VALUE! | C38: =C35 -> 1.44e+10 | D38: =D35 -> 1.44e+10
A39: New loan | B39: =$B$31 -> 1.44e+10 | C39: =$B$31 -> 1.44e+10 | D39: =$B$31 -> 1.44e+10
A42: TAXATION
A43: Tax | B43: 0.2 | C43: Per year | D43: Positive year net income
A46: LONG-TERM ASSETS & DEPRECIATION
A47: Please refer to "Item list" and "Spending" spreadsheets for further information
A51: II/ Operation
A53: PRODUCTION & SALES
A54: Production capacity | B54: =ROUNDDOWN(('Operations plan'!C61+'Operations plan'!C58)/B55,-2) -> 2400 | C54: Products/month | D54: Maximum
A55: Estimated mobilized | B55: 0.8 | C55: In general | D55: Production capaitcy
...

Sheet Delayed payment
A1: AR plan | G1: 2025 | T1: 2026 | AG1: 2027
G2: Q1 | J2: Q2 | M2: Q3 | P2: Q4 | T2: Q1 | W2: Q2 | Z2: Q3 | AC2: Q4 | AG2: Q1 | AJ2: Q2 | AM2: Q3 | AP2: Q4
G3: 1 | H3: 2 | I3: 3 | J3: 4 | K3: 5 | L3: 6 | M3: 7 | N3: 8 | O3: 9 | P3: 10 | Q3: 11 | R3: 12 | T3: 1 | U3: 2 | V3: 3 | W3: 4 | X3: 5 | Y3: 6 | Z3: 7 | AA3: 8 | AB3: 9 | AC3: 10 | AD3: 11 | AE3: 12 | AG3: 1 | AH3: 2 | AI3: 3 | AJ3: 4 | AK3: 5 | AL3: 6 | AM3: 7 | AN3: 8 | AO3: 9 | AP3: 10 | AQ3: 11 | AR3: 12
A4: Distributor vol. | C4: ='Operations plan'!C16 -> 1800 | D4: ='Operations plan'!D16 -> 0 | G4: ='Operations plan'!E16 -> 0 | H4: ='Operations plan'!F16 -> 0 | I4: ='Operations plan'!G16 -> 0 | J4: ='Operations plan'!H16 -> 0 | K4: ='Operations plan'!I16 -> 0 | L4: ='Operations plan'!J16 -> 1200 | M4: ='Operations plan'!K16 -> 1200 | N4: ='Operations plan'!L16 -> 1260 | ... R4: ='Operations plan'!P16 -> 1320 | T4: ='Operations plan'!R16 -> 1140 | U4: ='Operations plan'!S16 -> 1140 | V4: ='Operations plan'!T16 -> 1140 | W4: ='Operations plan'!U16 -> 1380 | X4: ='Operations plan'!V16 -> 1380 | Y4: ='Operations plan'!W16 -> 1380 | Z4: ='Operations plan'!X16 -> 1440 | AA4: ='Operations plan'!Y16 -> 1440 | ... AE4: ='Operations plan'!AC16 -> 1800 | AG4: ='Operations plan'!AE16 -> 1530 | AH4: ='Operations plan'!AF16 -> 1530 | AI4: ='Operations plan'!AG16 -> 1530 | AJ4: ='Operations plan'!AH16 -> 1800 | AK4: ='Operations plan'!AI16 -> 1800 | AL4: ='Operations plan'!AJ16 -> 1800 | AM4: ='Operations plan'!AK16 -> 1890 | AN4: ='Operations plan'!AL16 -> 1890 | ... AR4: ='Operations plan'!AP16 -> 1980
B5: Standard | C5: ='Operations plan'!C17 -> 1200 | D5: ='Operations plan'!D17 -> 1200 | G5: ='Operations plan'!E17 -> 0 | H5: ='Operations plan'!F17 -> 0 | I5: ='Operations plan'!G17 -> 0 | J5: ='Operations plan'!H17 -> 0 | K5: ='Operations plan'!I17 -> 0 | L5: ='Operations plan'!J17 -> 1200 | M5: ='Operations plan'!K17 -> 1200 | N5: ='Operations plan'!L17 -> 1260 | ... R5: ='Operations plan'!P17 -> 1320 | T5: ='Operations plan'!R17 -> 1140 | U5: ='Operations plan'!S17 -> 1140 | V5: ='Operations plan'!T17 -> 1140 | W5: ='Operations plan'!U17 -> 1380 | X5: ='Operations plan'!V17 -> 1380 | Y5: ='Operations plan'!W17 -> 1380 | Z5: ='Operations plan'!X17 -> 1440 | AA5: ='Operations plan'!Y17 -> 1440 | ... AE5: ='Operations plan'!AC17 -> 1500 | AG5: ='Operations plan'!AE17 -> 1320 | AH5: ='Operations plan'!AF17 -> 1320 | AI5: ='Operations plan'!AG17 -> 1320 | AJ5: ='Operations plan'!AH17 -> 1440 | AK5: ='Operations plan'!AI17 -> 1440 | AL5: ='Operations plan'!AJ17 -> 1440 | AM5: ='Operations plan'!AK17 -> 1500 | AN5: ='Operations plan'!AL17 -> 1500 | ... AR5: ='Operations plan'!AP17 -> 1560
B6: E-bike | C6: ='Operations plan'!C18 -> 600 | D6: ='Operations plan'!D18 -> 600 | G6: ='Operations plan'!E18 -> 0 | H6: ='Operations plan'!F18 -> 0 | I6: ='Operations plan'!G18 -> 0 | J6: ='Operations plan'!H18 -> 0 | K6: ='Operations plan'!I18 -> 0 | L6: ='Operations plan'!J18 -> 0 | M6: ='Operations plan'!K18 -> 0 | N6: ='Operations plan'!L18 -> 0 | ... R6: ='Operations plan'!P18 -> 0 | T6: ='Operations plan'!R18 -> 0 | U6: ='Operations plan'!S18 -> 0 | V6: ='Operations plan'!T18 -> 0 | W6: ='Operations plan'!U18 -> 0 | X6: ='Operations plan'!V18 -> 0 | Y6: ='Operations plan'!W18 -> 0 | Z6: ='Operations plan'!X18 -> 0 | AA6: ='Operations plan'!Y18 -> 0 | ... AE6: ='Operations plan'!AC18 -> 300 | AG6: ='Operations plan'!AE18 -> 210 | AH6: ='Operations plan'!AF18 -> 210 | AI6: ='Operations plan'!AG18 -> 210 | AJ6: ='Operations plan'!AH18 -> 360 | AK6: ='Operations plan'!AI18 -> 360 | AL6: ='Operations plan'!AJ18 -> 360 | AM6: ='Operations plan'!AK18 -> 390 | AN6: ='Operations plan'!AL18 -> 390 | ... AR6: ='Operations plan'!AP18 -> 420
A7: Dis. price | C7: ='Operations plan'!C37 -> Base \ Sale | D7: ='Operations plan'!D37 -> 18942000000 | G7: ='Operations plan'!E37 -> 0 | H7: ='Operations plan'!F37 -> 0 | I7: ='Operations plan'!G37 -> 0 | J7: ='Operations plan'!H37 -> 0 | K7: ='Operations plan'!I37 -> 0 | L7: ='Operations plan'!J37 -> 7333200000 | M7: ='Operations plan'!K37 -> 7333200000 | N7: ='Operations plan'!L37 -> 7699860000 | ... R7: ='Operations plan'!P37 -> 8066520000 | T7: ='Operations plan'!R37 -> 6966540000 | U7: ='Operations plan'!S37 -> 6966540000 | V7: ='Operations plan'!T37 -> 6966540000 | W7: ='Operations plan'!U37 -> 8433180000 | X7: ='Operations plan'!V37 -> 8433180000 | Y7: ='Operations plan'!W37 -> 8433180000 | Z7: ='Operations plan'!X37 -> 8799840000 | AA7: ='Operations plan'!Y37 -> 8799840000 | ... AE7: ='Operations plan'!AC37 -> 14023800000 | AG7: ='Operations plan'!AE37 -> 11466630000 | AH7: ='Operations plan'!AF37 -> 11466630000 | AI7: ='Operations plan'!AG37 -> 11466630000 | AJ7: ='Operations plan'!AH37 -> 14628600000 | AK7: ='Operations plan'!AI37 -> 14628600000 | AL7: ='Operations plan'!AJ37 -> 14628600000 | AM7: ='Operations plan'!AK37 -> 15480990000 | AN7: ='Operations plan'!AL37 -> 15480990000 | ... AR7: ='Operations plan'!AP37 -> 16333380000
B8: Standard | C8: ='Operations plan'!C38 -> 6790000 | D8: ='Operations plan'!D38 -> 6790000 | G8: ='Operations plan'!E38 -> 6111000 | H8: ='Operations plan'!F38 -> 6111000 | I8: ='Operations plan'!G38 -> 6111000 | J8: ='Operations plan'!H38 -> 6111000 | K8: ='Operations plan'!I38 -> 6111000 | L8: ='Operations plan'!J38 -> 6111000 | M8: ='Operations plan'!K38 -> 6111000 | N8: ='Operations plan'!L38 -> 6111000 | ... R8: ='Operations plan'!P38 -> 6111000 | T8: ='Operations plan'!R38 -> 6111000 | U8: ='Operations plan'!S38 -> 6111000 | V8: ='Operations plan'!T38 -> 6111000 | W8: ='Operations plan'!U38 -> 6111000 | X8: ='Operations plan'!V38 -> 6111000 | Y8: ='Operations plan'!W38 -> 6111000 | Z8: ='Operations plan'!X38 -> 6111000 | AA8: ='Operations plan'!Y38 -> 6111000 | ... AE8: ='Operations plan'!AC38 -> 6111000 | AG8: ='Operations plan'!AE38 -> 6111000 | AH8: ='Operations plan'!AF38 -> 6111000 | AI8: ='Operations plan'!AG38 -> 6111000 | AJ8: ='Operations plan'!AH38 -> 6111000 | AK8: ='Operations plan'!AI38 -> 6111000 | AL8: ='Operations plan'!AJ38 -> 6111000 | AM8: ='Operations plan'!AK38 -> 6111000 | AN8: ='Operations plan'!AL38 -> 6111000 | ... AR8: ='Operations plan'!AP38 -> 6111000
B9: E-bike | C9: ='Operations plan'!C39 -> 17990000 | D9: ='Operations plan'!D39 -> 17990000 | G9: ='Operations plan'!E39 -> 16191000 | H9: ='Operations plan'!F39 -> 16191000 | I9: ='Operations plan'!G39 -> 16191000 | J9: ='Operations plan'!H39 -> 16191000 | K9: ='Operations plan'!I39 -> 16191000 | L9: ='Operations plan'!J39 -> 16191000 | M9: ='Operations plan'!K39 -> 16191000 | N9: ='Operations plan'!L39 -> 16191000 | ... R9: ='Operations plan'!P39 -> 16191000 | T9: ='Operations plan'!R39 -> 16191000 | U9: ='Operations plan'!S39 -> 16191000 | V9: ='Operations plan'!T39 -> 16191000 | W9: ='Operations plan'!U39 -> 16191000 | X9: ='Operations plan'!V39 -> 16191000 | Y9: ='Operations plan'!W39 -> 16191000 | Z9: ='Operations plan'!X39 -> 16191000 | AA9: ='Operations plan'!Y39 -> 16191000 | ... AE9: ='Operations plan'!AC39 -> 16191000 | AG9: ='Operations plan'!AE39 -> 16191000 | AH9: ='Operations plan'!AF39 -> 16191000 | AI9: ='Operations plan'!AG39 -> 16191000 | AJ9: ='Operations plan'!AH39 -> 16191000 | AK9: ='Operations plan'!AI39 -> 16191000 | AL9: ='Operations plan'!AJ39 -> 16191000 | AM9: ='Operations plan'!AK39 -> 16191000 | AN9: ='Operations plan'!AL39 -> 16191000 | ... AR9: ='Operations plan'!AP39 -> 16191000
A11: Trả | B11: Trả ngay | C11: =Parameter!B8 -> 0.5 | G11: =$C11*G$7 -> 0 | H11: =$C11*H7 -> 0 | I11: =$C11*I7 -> 0 | J11: =$C11*J7 -> 0 | K11: =$C11*K7 -> 0 | L11: =$C11*L7 -> 3666600000 | M11: =$C11*M7 -> 3666600000 | N11: =$C11*N7 -> 3849930000 | O11: =$C11*O7 -> 3849930000 | ... R11: =$C11*R7 -> 4033260000 | T11: =$C11*T7 -> 3483270000 | U11: =$C11*U7 -> 3483270000 | V11: =$C11*V7 -> 3483270000 | W11: =$C11*W7 -> 4216590000 | X11: =$C11*X7 -> 4216590000 | Y11: =$C11*Y7 -> 4216590000 | Z11: =$C11*Z7 -> 4399920000 | AA11: =$C11*AA7 -> 4399920000 | ... AE11: =$C11*AE7 -> 7011900000 | AG11: =$C11*AG7 -> 5733315000 | AH11: =$C11*AH7 -> 5733315000 | AI11: =$C11*AI7 -> 5733315000 | AJ11: =$C11*AJ7 -> 7314300000 | AK11: =$C11*AK7 -> 7314300000 | AL11: =$C11*AL7 -> 7314300000 | AM11: =$C11*AM7 -> 7740495000 | AN11: =$C11*AN7 -> 7740495000 | ... AR11: =$C11*AR7 -> 8166690000
B12: Trả 1 kì trước
B13: Trả 2 kì trước | C13: =Parameter!B10 -> 0.2 | G13: =$C13*G9 -> 3238200 | H13: =$C13*H9 -> 3238200 | I13: =$C13*I9 -> 3238200 | J13: =$C13*J9 -> 3238200 | K13: =$C13*K9 -> 3238200 | L13: =$C13*L9 -> 3238200 | M13: =$C13*M9 -> 3238200 | N13: =$C13*N9 -> 3238200 | ... R13: =$C13*R9 -> 3238200 | T13: =$C13*T9 -> 3238200 | U13: =$C13*U9 -> 3238200 | V13: =$C13*V9 -> 3238200 | W13: =$C13*W9 -> 3238200 | X13: =$C13*X9 -> 3238200 | Y13: =$C13*Y9 -> 3238200 | Z13: =$C13*Z9 -> 3238200 | AA13: =$C13*AA9 -> 3238200 | ... AE13: =$C13*AE9 -> 3238200 | AG13: =$C13*AG9 -> 3238200 | AH13: =$C13*AH9 -> 3238200 | AI13: =$C13*AI9 -> 3238200 | AJ13: =$C13*AJ9 -> 3238200 | AK13: =$C13*AK9 -> 3238200 | AL13: =$C13*AL9 -> 3238200 | AM13: =$C13*AM9 -> 3238200 | AN13: =$C13*AN9 -> 3238200 | ... AR13: =$C13*AR9 -> 3238200
B17: Nợ 1 kì trước | C17: =Parameter!B9 -> 0.3 | G17: =IF( ISBLANK(#REF!), IF( ISBLANK(D$3), 0, D$7 *$C17 ),#REF! * $C17 ) -> #REF! | H17: =IF( ISBLANK(G$3), IF( ISBLANK(#REF!), 0,#REF! * $C17 ), G$7 * $C17 ) -> 0 | I17: =IF( ISBLANK(H$3), IF( ISBLANK(G$3), 0, G$7 *$C17 ), H$7 * $C17 ) -> 0 | J17: =IF( ISBLANK(I$3), IF( ISBLANK(H$3), 0, H$7 *$C17 ), I$7 * $C17 ) -> 0 | K17: =IF( ISBLANK(J$3), IF( ISBLANK(I$3), 0, I$7 *$C17 ), J$7 * $C17 ) -> 0 | L17: =IF( ISBLANK(K$3), IF( ISBLANK(J$3), 0, J$7 *$C17 ), K$7 * $C17 ) -> 0 | M17: =IF( ISBLANK(L$3), IF( ISBLANK(K$3), 0, K$7 *$C17 ), L$7 * $C17 ) -> 2199960000 | N17: =IF( ISBLANK(M$3), IF( ISBLANK(L$3), 0, L$7 *$C17 ), M$7 * $C17 ) -> 2199960000 | O17: =IF( ISBLANK(N$3), IF( ISBLANK(M$3), 0, M$7 *$C17 ), N$7 * $C17 ) -> 2309958000 | P17: =IF( ISBLANK(O$3), IF( ISBLANK(N$3), 0, N$7 *$C17 ), O$7 * $C17 ) -> 2309958000 | ... R17: =IF( ISBLANK(Q$3), IF( ISBLANK(P$3), 0, P$7 *$C17 ), Q$7 * $C17 ) -> 2419956000 | T17: =IF( ISBLANK(#REF!), IF( ISBLANK(R$3), 0, R$7 *$C17 ),#REF! * $C17 ) -> #REF! | U17: =IF( ISBLANK(T$3), IF( ISBLANK(#REF!), 0,#REF! * $C17 ), T$7 * $C17 ) -> 2089962000 | V17: =IF( ISBLANK(U$3), IF( ISBLANK(T$3), 0, T$7 *$C17 ), U$7 * $C17 ) -> 2089962000 | W17: =IF( ISBLANK(V$3), IF( ISBLANK(U$3), 0, U$7 *$C17 ), V$7 * $C17 ) -> 2089962000 | X17: =IF( ISBLANK(W$3), IF( ISBLANK(V$3), 0, V$7 *$C17 ), W$7 * $C17 ) -> 2529954000 | Y17: =IF( ISBLANK(X$3), IF( ISBLANK(W$3), 0, W$7 *$C17 ), X$7 * $C17 ) -> 2529954000 | Z17: =IF( ISBLANK(Y$3), IF( ISBLANK(X$3), 0, X$7 *$C17 ), Y$7 * $C17 ) -> 2529954000 | AA17: =IF( ISBLANK(Z$3), IF( ISBLANK(Y$3), 0, Y$7 *$C17 ), Z$7 * $C17 ) -> 2639952000 | AB17: =IF( ISBLANK(AA$3), IF( ISBLANK(Z$3), 0, Z$7 *$C17 ), AA$7 * $C17 ) -> 2639952000 | AC17: =IF( ISBLANK(AB$3), IF( ISBLANK(AA$3), 0, AA$7 *$C17 ), AB$7 * $C17 ) -> 2639952000 | ... AE17: =IF( ISBLANK(AD$3), IF( ISBLANK(AC$3), 0, AC$7 *$C17 ), AD$7 * $C17 ) -> 4207140000 | AG17: =IF( ISBLANK(#REF!), IF( ISBLANK(AE$3), 0, AE$7 *$C17 ),#REF! * $C17 ) -> #REF! | AH17: =IF( ISBLANK(AG$3), IF( ISBLANK(#REF!), 0,#REF! * $C17 ), AG$7 * $C17 ) -> 3439989000 | AI17: =IF( ISBLANK(AH$3), IF( ISBLANK(AG$3), 0, AG$7 *$C17 ), AH$7 * $C17 ) -> 3439989000 | AJ17: =IF( ISBLANK(AI$3), IF( ISBLANK(AH$3), 0, AH$7 *$C17 ), AI$7 * $C17 ) -> 3439989000 | AK17: =IF( ISBLANK(AJ$3), IF( ISBLANK(AI$3), 0, AI$7 *$C17 ), AJ$7 * $C17 ) -> 4388580000 | AL17: =IF( ISBLANK(AK$3), IF( ISBLANK(AJ$3), 0, AJ$7 *$C17 ), AK$7 * $C17 ) -> 4388580000 | AM17: =IF( ISBLANK(AL$3), IF( ISBLANK(AK$3), 0, AK$7 *$C17 ), AL$7 * $C17 ) -> 4388580000 | AN17: =IF( ISBLANK(AM$3), IF( ISBLANK(AL$3), 0, AL$7 *$C17 ), AM$7 * $C17 ) -> 4644297000 | AO17: =IF( ISBLANK(AN$3), IF( ISBLANK(AM$3), 0, AM$7 *$C17 ), AN$7 * $C17 ) -> 4644297000 | AP17: =IF( ISBLANK(AO$3), IF( ISBLANK(AN$3), 0, AN$7 *$C17 ), AO$7 * $C17 ) -> 4790016000 | ... AR17: =IF( ISBLANK(AQ$3), IF( ISBLANK(AP$3), 0, AP$7 *$C17 ), AQ$7 * $C17 ) -> 4900014000
B18: Nợ 2 kì trước | G18: =IF( ISBLANK(#REF!), IF( ISBLANK(D$3), 0, D$7 *$C18 ),#REF! * $C18 ) -> #REF! | H18: =IF( ISBLANK(G$3), IF( ISBLANK(#REF!), 0,#REF! * $C18 ), G$7 * $C18 ) -> 0 | I18: =IF( ISBLANK(H$3), IF( ISBLANK(G$3), 0, G$7 *$C18 ), H$7 * $C18 ) -> 0 | J18: =IF( ISBLANK(I$3), IF( ISBLANK(H$3), 0, H$7 *$C18 ), I$7 * $C18 ) -> 0 | K18: =IF( ISBLANK(J$3), IF( ISBLANK(I$3), 0, I$7 *$C18 ), J$7 * $C18 ) -> 0 | L18: =IF( ISBLANK(K$3), IF( ISBLANK(J$3), 0, J$7 *$C18 ), K$7 * $C18 ) -> 0 | M18: =IF( ISBLANK(L$3), IF( ISBLANK(K$3), 0, K$7 *$C18 ), L$7 * $C18 ) -> 0 | N18: =IF( ISBLANK(M$3), IF( ISBLANK(L$3), 0, L$7 *$C18 ), M$7 * $C18 ) -> 0 | O18: =IF( ISBLANK(N$3), IF( ISBLANK(M$3), 0, M$7 *$C18 ), N$7 * $C18 ) -> 0 | P18: =IF( ISBLANK(O$3), IF( ISBLANK(N$3), 0, N$7 *$C18 ), O$7 * $C18 ) -> 0 | ... R18: =IF( ISBLANK(Q$3), IF( ISBLANK(P$3), 0, P$7 *$C18 ), Q$7 * $C18 ) -> 0 | T18: =IF( ISBLANK(#REF!), IF( ISBLANK(R$3), 0, R$7 *$C18 ),#REF! * $C18 ) -> #REF! | U18: =IF( ISBLANK(T$3), IF( ISBLANK(#REF!), 0,#REF! * $C18 ), T$7 * $C18 ) -> 0 | V18: =IF( ISBLANK(U$3), IF( ISBLANK(T$3), 0, T$7 *$C18 ), U$7 * $C18 ) -> 0 | W18: =IF( ISBLANK(V$3), IF( ISBLANK(U$3), 0, U$7 *$C18 ), V$7 * $C18 ) -> 0 | X18: =IF( ISBLANK(W$3), IF( ISBLANK(V$3), 0, V$7 *$C18 ), W$7 * $C18 ) -> 0 | Y18: =IF( ISBLANK(X$3), IF( ISBLANK(W$3), 0, W$7 *$C18 ), X$7 * $C18 ) -> 0 | Z18: =IF( ISBLANK(Y$3), IF( ISBLANK(X$3), 0, X$7 *$C18 ), Y$7 * $C18 ) -> 0 | AA18: =IF( ISBLANK(Z$3), IF( ISBLANK(Y$3), 0, Y$7 *$C18 ), Z$7 * $C18 ) -> 0 | AB18: =IF( ISBLANK(AA$3), IF( ISBLANK(Z$3), 0, Z$7 *$C18 ), AA$7 * $C18 ) -> 0 | AC18: =IF( ISBLANK(AB$3), IF( ISBLANK(AA$3), 0, AA$7 *$C18 ), AB$7 * $C18 ) -> 0 | ... AE18: =IF( ISBLANK(AD$3), IF( ISBLANK(AC$3), 0, AC$7 *$C18 ), AD$7 * $C18 ) -> 0 | AG18: =IF( ISBLANK(#REF!), IF( ISBLANK(AE$3), 0, AE$7 *$C18 ),#REF! * $C18 ) -> #REF! | AH18: =IF( ISBLANK(AG$3), IF( ISBLANK(#REF!), 0,#REF! * $C18 ), AG$7 * $C18 ) -> 0 | AI18: =IF( ISBLANK(AH$3), IF( ISBLANK(AG$3), 0, AG$7 *$C18 ), AH$7 * $C18 ) -> 0 | AJ18: =IF( ISBLANK(AI$3), IF( ISBLANK(AH$3), 0, AH$7 *$C18 ), AI$7 * $C18 ) -> 0 | AK18: =IF( ISBLANK(AJ$3), IF( ISBLANK(AI$3), 0, AI$7 *$C18 ), AJ$7 * $C18 ) -> 0 | AL18: =IF( ISBLANK(AK$3), IF( ISBLANK(AJ$3), 0, AJ$7 *$C18 ), AK$7 * $C18 ) -> 0 | AM18: =IF( ISBLANK(AL$3), IF( ISBLANK(AK$3), 0, AK$7 *$C18 ), AL$7 * $C18 ) -> 0 | AN18: =IF( ISBLANK(AM$3), IF( ISBLANK(AL$3), 0, AL$7 *$C18 ), AM$7 * $C18 ) -> 0 | AO18: =IF( ISBLANK(AN$3), IF( ISBLANK(AM$3), 0, AM$7 *$C18 ), AN$7 * $C18 ) -> 0 | AP18: =IF( ISBLANK(AO$3), IF( ISBLANK(AN$3), 0, AN$7 *$C18 ), AO$7 * $C18 ) -> 0 | ... AR18: =IF( ISBLANK(AQ$3), IF( ISBLANK(AP$3), 0, AP$7 *$C18 ), AQ$7 * $C18 ) -> 0
A20: On purchase | B20: =Parameter!B8 -> 0.5 | G20: =$B20*G$7 -> 0 | H20: =$B20*H$7 -> 0 | I20: =$B20*I$7 -> 0 | J20: =$B20*J$7 -> 0 | K20: =$B20*K$7 -> 0 | L20: =$B20*L$7 -> 3666600000 | M20: =$B20*M$7 -> 3666600000 | N20: =$B20*N$7 -> 3849930000 | ... R20: =$B20*R$7 -> 4033260000 | T20: =$B20*T$7 -> 3483270000 | U20: =$B20*U$7 -> 3483270000 | V20: =$B20*V$7 -> 3483270000 | W20: =$B20*W$7 -> 4216590000 | X20: =$B20*X$7 -> 4216590000 | Y20: =$B20*Y$7 -> 4216590000 | Z20: =$B20*Z$7 -> 4399920000 | AA20: =$B20*AA$7 -> 4399920000 | ... AE20: =$B20*AE$7 -> 7011900000 | AG20: =$B20*AG$7 -> 5733315000 | AH20: =$B20*AH$7 -> 5733315000 | AI20: =$B20*AI$7 -> 5733315000 | AJ20: =$B20*AJ$7 -> 7314300000 | AK20: =$B20*AK$7 -> 7314300000 | AL20: =$B20*AL$7 -> 7314300000 | AM20: =$B20*AM$7 -> 7740495000 | AN20: =$B20*AN$7 -> 7740495000 | ... AT20: =$B20*AT$7 -> 0
A21: For 1st prior period | B21: =Parameter!B9 -> 0.3 | G21: =F$7*$B21 -> 0 | H21: =G$7*$B21 -> 0 | I21: =H$7*$B21 -> 0 | J21: =I$7*$B21 -> 0 | K21: =J$7*$B21 -> 0 | L21: =K$7*$B21 -> 0 | M21: =L$7*$B21 -> 2199960000 | N21: =M$7*$B21 -> 2199960000 | ... R21: =Q$7*$B21 -> 2419956000 | T21: =R$7*$B21 -> 2419956000 | U21: =T$7*$B21 -> 2089962000 | V21: =U$7*$B21 -> 2089962000 | W21: =V$7*$B21 -> 2089962000 | X21: =W$7*$B21 -> 2529954000 | Y21: =X$7*$B21 -> 2529954000 | Z21: =Y$7*$B21 -> 2529954000 | AA21: =Z$7*$B21 -> 2639952000 | AB21: =AA$7*$B21 -> 2639952000 | ... AE21: =AD$7*$B21 -> 4207140000 | AG21: =AE$7*$B21 -> 4207140000 | AH21: =AG$7*$B21 -> 3439989000 | AI21: =AH$7*$B21 -> 3439989000 | AJ21: =AI$7*$B21 -> 3439989000 | AK21: =AJ$7*$B21 -> 4388580000 | AL21: =AK$7*$B21 -> 4388580000 | AM21: =AL$7*$B21 -> 4388580000 | AN21: =AM$7*$B21 -> 4644297000 | AO21: =AN$7*$B21 -> 4644297000 | ... AT21: =AS$7*$B21 -> 0
A22: For 2nd prior period | B22: =Parameter!B10 -> 0.2 | G22: =E$7*$B22 -> 0 | H22: =F$7*$B22 -> 0 | I22: =G$7*$B22 -> 0 | J22: =H$7*$B22 -> 0 | K22: =I$7*$B22 -> 0 | L22: =J$7*$B22 -> 0 | M22: =K$7*$B22 -> 0 | N22: =L$7*$B22 -> 1466640000 | ... R22: =P$7*$B22 -> 1613304000 | T22: =Q$7*$B22 -> 1613304000 | U22: =R$7*$B22 -> 1613304000 | V22: =T$7*$B22 -> 1393308000 | W22: =U$7*$B22 -> 1393308000 | X22: =V$7*$B22 -> 1393308000 | Y22: =W$7*$B22 -> 1686636000 | Z22: =X$7*$B22 -> 1686636000 | AA22: =Y$7*$B22 -> 1686636000 | AB22: =Z$7*$B22 -> 1759968000 | AC22: =AA$7*$B22 -> 1759968000 | ... AE22: =AC$7*$B22 -> 1833300000 | AG22: =AD$7*$B22 -> 2804760000 | AH22: =AE$7*$B22 -> 2804760000 | AI22: =AG$7*$B22 -> 2293326000 | AJ22: =AH$7*$B22 -> 2293326000 | AK22: =AI$7*$B22 -> 2293326000 | AL22: =AJ$7*$B22 -> 2925720000 | AM22: =AK$7*$B22 -> 2925720000 | AN22: =AL$7*$B22 -> 2925720000 | AO22: =AM$7*$B22 -> 3096198000 | AP22: =AN$7*$B22 -> 3096198000 | ... AT22: =AR$7*$B22 -> 3266676000
A23: TOTAL PAYMENT | G23: =SUM(G20:G22) -> 0 | H23: =SUM(H20:H22) -> 0 | I23: =SUM(I20:I22) -> 0 | J23: =SUM(J20:J22) -> 0 | K23: =SUM(K20:K22) -> 0 | L23: =SUM(L20:L22) -> 3666600000 | M23: =SUM(M20:M22) -> 5866560000 | N23: =SUM(N20:N22) -> 7516530000 | ... R23: =SUM(R20:R22) -> 8066520000 | T23: =SUM(T20:T22) -> 7516530000 | U23: =SUM(U20:U22) -> 7186536000 | V23: =SUM(V20:V22) -> 6966540000 | W23: =SUM(W20:W22) -> 7699860000 | X23: =SUM(X20:X22) -> 8139852000 | Y23: =SUM(Y20:Y22) -> 8433180000 | Z23: =SUM(Z20:Z22) -> 8616510000 | AA23: =SUM(AA20:AA22) -> 8726508000 | ... AE23: =SUM(AE20:AE22) -> 13052340000 | AG23: =SUM(AG20:AG22) -> 12745215000 | AH23: =SUM(AH20:AH22) -> 11978064000 | AI23: =SUM(AI20:AI22) -> 11466630000 | AJ23: =SUM(AJ20:AJ22) -> 13047615000 | AK23: =SUM(AK20:AK22) -> 13996206000 | AL23: =SUM(AL20:AL22) -> 14628600000 | AM23: =SUM(AM20:AM22) -> 15054795000 | AN23: =SUM(AN20:AN22) -> 15310512000 | ... AT23: =SUM(AT20:AT22) -> 3266676000
A24: Recievable (Offseting):
A25: For 1st following period | F25: =G21 -> 0 | G25: =H21 -> 0 | H25: =I21 -> 0 | I25: =J21 -> 0 | J25: =K21 -> 0 | K25: =L21 -> 0 | L25: =M21 -> 2199960000 | M25: =N21 -> 2199960000 | ... Q25: =R21 -> 2419956000 | R25: =T21 -> 2419956000 | T25: =U21 -> 2089962000 | U25: =V21 -> 2089962000 | V25: =W21 -> 2089962000 | W25: =X21 -> 2529954000 | X25: =Y21 -> 2529954000 | Y25: =Z21 -> 2529954000 | Z25: =AA21 -> 2639952000 | AA25: =AB21 -> 2639952000 | ... AD25: =AE21 -> 4207140000 | AE25: =AG21 -> 4207140000 | AF25: =IF(ISBLANK(AF3),AE25) -> 4207140000 | AG25: =AH21 -> 3439989000 | AH25: =AI21 -> 3439989000 | AI25: =AJ21 -> 3439989000 | AJ25: =AK21 -> 4388580000 | AK25: =AL21 -> 4388580000 | AL25: =AM21 -> 4388580000 | AM25: =AN21 -> 4644297000 | AN25: =AO21 -> 4644297000 | ... AS25: =AT21 -> 0 | AT25: =BA21 -> 0
A26: For 2nd following period | E26: =G22 -> 0 | F26: =H22 -> 0 | G26: =I22 -> 0 | H26: =J22 -> 0 | I26: =K22 -> 0 | J26: =L22 -> 0 | K26: =M22 -> 0 | L26: =N22 -> 1466640000 | ... P26: =R22 -> 1613304000 | Q26: =T22 -> 1613304000 | R26: =U22 -> 1613304000 | T26: =V22 -> 1393308000 | U26: =W22 -> 1393308000 | V26: =X22 -> 1393308000 | W26: =Y22 -> 1686636000 | X26: =Z22 -> 1686636000 | Y26: =AA22 -> 1686636000 | Z26: =AB22 -> 1759968000 | AA26: =AC22 -> 1759968000 | ... AC26: =AE22 -> 1833300000 | AD26: =AG22 -> 2804760000 | AE26: =AH22 -> 2804760000 | AF26: =IF(ISBLANK(AF3),AE26) -> 2804760000 | AG26: =AI22 -> 2293326000 | AH26: =AJ22 -> 2293326000 | AI26: =AK22 -> 2293326000 | AJ26: =AL22 -> 2925720000 | AK26: =AM22 -> 2925720000 | AL26: =AN22 -> 2925720000 | AM26: =AO22 -> 3096198000 | AN26: =AP22 -> 3096198000 | ... AR26: =AT22 -> 3266676000 | AS26: =BA22 -> 0 | AT26: =BB22 -> 0
A27: ACCOUNT RECEIVABLE | G27: =SUM(G25:G26)-SUM(G21:G22)+F27 -> 0 | H27: =SUM(H25:H26)-SUM(H21:H22)+G27 -> 0 | I27: =SUM(I25:I26)-SUM(I21:I22)+H27 -> 0 | J27: =SUM(J25:J26)-SUM(J21:J22)+I27 -> 0 | K27: =SUM(K25:K26)-SUM(K21:K22)+J27 -> 0 | L27: =SUM(L25:L26)-SUM(L21:L22)+K27 -> 3666600000 | M27: =SUM(M25:M26)-SUM(M21:M22)+L27 -> 5133240000 | N27: =SUM(N25:N26)-SUM(N21:N22)+M27 -> 5316570000 | ... AE27: =SUM(AE25:AE26)-SUM(AE21:AE22)+AD27 -> 9816660000 | AG27: =SUM(AG25:AG26)-SUM(AG21:AG22)+AE27 -> 8538075000 | AH27: =SUM(AH25:AH26)-SUM(AH21:AH22)+AG27 -> 8026641000 | AI27: =SUM(AI25:AI26)-SUM(AI21:AI22)+AH27 -> 8026641000 | AJ27: =SUM(AJ25:AJ26)-SUM(AJ21:AJ22)+AI27 -> 9607626000 | AK27: =SUM(AK25:AK26)-SUM(AK21:AK22)+AJ27 -> 10240020000 | AL27: =SUM(AL25:AL26)-SUM(AL21:AL22)+AK27 -> 10240020000 | AM27: =SUM(AM25:AM26)-SUM(AM21:AM22)+AL27 -> 10666215000 | AN27: =SUM(AN25:AN26)-SUM(AN21:AN22)+AM27 -> 10836693000 | AO27: =SUM(AO25:AO26)-SUM(AO21:AO22)+AN27 -> 11079558000 | ... AT27: =SUM(AT25:AT26)-SUM(AT21:AT22)+AS27 -> 0
A30: AP plan | G30: 2025 | T30: 2026 | AG30: 2027
G31: Q1 | J31: Q2 | M31: Q3 | P31: Q4 | T31: Q1 | W31: Q2 | Z31: Q3 | AC31: Q4 | AG31: Q1 | AJ31: Q2 | AM31: Q3 | AP31: Q4
G32: 1 | H32: 2 | I32: 3 | J32: 4 | K32: 5 | L32: 6 | M32: 7 | N32: 8 | O32: 9 | P32: 10 | Q32: 11 | R32: 12 | T32: 1 | U32: 2 | V32: 3 | W32: 4 | X32: 5 | Y32: 6 | Z32: 7 | AA32: 8 | AB32: 9 | AC32: 10 | AD32: 11 | AE32: 12 | AG32: 1 | AH32: 2 | AI32: 3 | AJ32: 4 | AK32: 5 | AL32: 6 | AM32: 7 | AN32: 8 | AO32: 9 | AP32: 10 | AQ32: 11 | AR32: 12
A33: Production outputs | C33: Mat cost | E33: =SUM(E34:E35) -> 0 | F33: =SUM(F34:F35) -> 0 | G33: ='Operations plan'!E77 -> 0 | H33: ='Operations plan'!F77 -> 0 | I33: ='Operations plan'!G77 -> 0 | J33: ='Operations plan'!H77 -> 0 | K33: ='Operations plan'!I77 -> 274 | L33: ='Operations plan'!J77 -> 1200 | M33: ='Operations plan'!K77 -> 1219 | N33: ='Operations plan'!L77 -> 1350 | ... R33: ='Operations plan'!P77 -> 1389 | T33: ='Operations plan'!R77 -> 1204 | U33: ='Operations plan'!S77 -> 1204 | V33: ='Operations plan'!T77 -> 1237 | W33: ='Operations plan'!U77 -> 1476 | X33: ='Operations plan'!V77 -> 1476 | Y33: ='Operations plan'!W77 -> 1483 | Z33: ='Operations plan'!X77 -> 1532 | AA33: ='Operations plan'!Y77 -> 1532 | ... AE33: ='Operations plan'!AC77 -> 1878 | AG33: ='Operations plan'!AE77 -> 1651 | AH33: ='Operations plan'!AF77 -> 1641 | AI33: ='Operations plan'!AG77 -> 1679 | AJ33: ='Operations plan'!AH77 -> 1962 | AK33: ='Operations plan'!AI77 -> 1962 | AL33: ='Operations plan'!AJ77 -> 1971 | AM33: ='Operations plan'!AK77 -> 2042 | AN33: ='Operations plan'!AL77 -> 2046 | ... AR33: ='Operations plan'!AP77 -> 1906
B34: Standard | C34: =Parameter!B65 -> 3350000 | E34: =E21+E24+E31 -> 0 | F34: =F21+F24+F31 -> 0 | G34: ='Operations plan'!E78 -> 0 | H34: ='Operations plan'!F78 -> 0 | I34: ='Operations plan'!G78 -> 0 | J34: ='Operations plan'!H78 -> 0 | K34: ='Operations plan'!I78 -> 274 | L34: ='Operations plan'!J78 -> 1200 | M34: ='Operations plan'!K78 -> 1219 | N34: ='Operations plan'!L78 -> 1350 | ... R34: ='Operations plan'!P78 -> 1389 | T34: ='Operations plan'!R78 -> 1204 | U34: ='Operations plan'!S78 -> 1204 | V34: ='Operations plan'!T78 -> 1237 | W34: ='Operations plan'!U78 -> 1476 | X34: ='Operations plan'!V78 -> 1476 | Y34: ='Operations plan'!W78 -> 1483 | Z34: ='Operations plan'!X78 -> 1532 | AA34: ='Operations plan'!Y78 -> 1532 | ... AE34: ='Operations plan'!AC78 -> 1582 | AG34: ='Operations plan'!AE78 -> 1391 | AH34: ='Operations plan'!AF78 -> 1391 | AI34: ='Operations plan'!AG78 -> 1409 | AJ34: ='Operations plan'!AH78 -> 1547 | AK34: ='Operations plan'!AI78 -> 1547 | AL34: ='Operations plan'!AJ78 -> 1553 | AM34: ='Operations plan'!AK78 -> 1598 | AN34: ='Operations plan'!AL78 -> 1598 | ... AR34: ='Operations plan'!AP78 -> 1482
B35: E-bike | C35: =Parameter!B66 -> 10800000 | E35: =E22+E25+E32 -> 0 | F35: =F22+F25+F32 -> 0 | G35: ='Operations plan'!E79 -> 0 | H35: ='Operations plan'!F79 -> 0 | I35: ='Operations plan'!G79 -> 0 | J35: ='Operations plan'!H79 -> 0 | K35: ='Operations plan'!I79 -> 0 | L35: ='Operations plan'!J79 -> 0 | M35: ='Operations plan'!K79 -> 0 | N35: ='Operations plan'!L79 -> 0 | ... R35: ='Operations plan'!P79 -> 0 | T35: ='Operations plan'!R79 -> 0 | U35: ='Operations plan'!S79 -> 0 | V35: ='Operations plan'!T79 -> 0 | W35: ='Operations plan'!U79 -> 0 | X35: ='Operations plan'!V79 -> 0 | Y35: ='Operations plan'!W79 -> 0 | Z35: ='Operations plan'!X79 -> 0 | AA35: ='Operations plan'!Y79 -> 0 | ... AE35: ='Operations plan'!AC79 -> 296 | AG35: ='Operations plan'!AE79 -> 260 | AH35: ='Operations plan'!AF79 -> 250 | AI35: ='Operations plan'!AG79 -> 270 | AJ35: ='Operations plan'!AH79 -> 415 | AK35: ='Operations plan'!AI79 -> 415 | AL35: ='Operations plan'!AJ79 -> 418 | AM35: ='Operations plan'!AK79 -> 444 | AN35: ='Operations plan'!AL79 -> 448 | ... AR35: ='Operations plan'!AP79 -> 424
A38: On purchase | B38: =Parameter!B11 -> 0.7 | C38: =Parameter!B11 -> 0.7 | G38: =$C38*SUMPRODUCT($C$34:$C$35,G34:G35) -> 0 | H38: =$C38*SUMPRODUCT($C$34:$C$35,H34:H35) -> 0 | I38: =$C38*SUMPRODUCT($C$34:$C$35,I34:I35) -> 0 | J38: =$C38*SUMPRODUCT($C$34:$C$35,J34:J35) -> 0 | K38: =$C38*SUMPRODUCT($C$34:$C$35,K34:K35) -> 642530000 | L38: =$C38*SUMPRODUCT($C$34:$C$35,L34:L35) -> 2814000000 | M38: =$C38*SUMPRODUCT($C$34:$C$35,M34:M35) -> 2858555000 | N38: =$C38*SUMPRODUCT($C$34:$C$35,N34:N35) -> 3165750000 | ... R38: =$C38*SUMPRODUCT($C$34:$C$35,R34:R35) -> 3257205000 | T38: =$C38*SUMPRODUCT($C$34:$C$35,T34:T35) -> 2823380000 | U38: =$C38*SUMPRODUCT($C$34:$C$35,U34:U35) -> 2823380000 | V38: =$C38*SUMPRODUCT($C$34:$C$35,V34:V35) -> 2900765000 | W38: =$C38*SUMPRODUCT($C$34:$C$35,W34:W35) -> 3461220000 | X38: =$C38*SUMPRODUCT($C$34:$C$35,X34:X35) -> 3461220000 | Y38: =$C38*SUMPRODUCT($C$34:$C$35,Y34:Y35) -> 3477635000 | Z38: =$C38*SUMPRODUCT($C$34:$C$35,Z34:Z35) -> 3592540000 | AA38: =$C38*SUMPRODUCT($C$34:$C$35,AA34:AA35) -> 3592540000 | ... AE38: =$C38*SUMPRODUCT($C$34:$C$35,AE34:AE35) -> 5947550000 | AG38: =$C38*SUMPRODUCT($C$34:$C$35,AG34:AG35) -> 5227495000 | AH38: =$C38*SUMPRODUCT($C$34:$C$35,AH34:AH35) -> 5151895000 | AI38: =$C38*SUMPRODUCT($C$34:$C$35,AI34:AI35) -> 5345305000 | AJ38: =$C38*SUMPRODUCT($C$34:$C$35,AJ34:AJ35) -> 6765115000 | AK38: =$C38*SUMPRODUCT($C$34:$C$35,AK34:AK35) -> 6765115000 | AL38: =$C38*SUMPRODUCT($C$34:$C$35,AL34:AL35) -> 6801865000 | AM38: =$C38*SUMPRODUCT($C$34:$C$35,AM34:AM35) -> 7103950000 | AN38: =$C38*SUMPRODUCT($C$34:$C$35,AN34:AN35) -> 7134190000 | ... AR38: =$C38*SUMPRODUCT($C$34:$C$35,AR34:AR35) -> 6680730000
A39: For prior period | B39: =Parameter!B12 -> 0.3 | C39: =Parameter!B12 -> 0.3 | G39: =$C39*SUMPRODUCT($C$34:$C$35,F34:F35) -> 0 | H39: =$C39*SUMPRODUCT($C$34:$C$35,G34:G35) -> 0 | I39: =$C39*SUMPRODUCT($C$34:$C$35,H34:H35) -> 0 | J39: =$C39*SUMPRODUCT($C$34:$C$35,I34:I35) -> 0 | K39: =$C39*SUMPRODUCT($C$34:$C$35,J34:J35) -> 0 | L39: =$C39*SUMPRODUCT($C$34:$C$35,K34:K35) -> 2.7537e+08 | M39: =$C39*SUMPRODUCT($C$34:$C$35,L34:L35) -> 1.206e+09 | N39: =$C39*SUMPRODUCT($C$34:$C$35,M34:M35) -> 1.225095e+09 | ... R39: =$C39*SUMPRODUCT($C$34:$C$35,Q34:Q35) -> 1.422075e+09 | T39: =$C39*SUMPRODUCT($C$34:$C$35,R34:R35) -> 1.395945e+09 | U39: =$C39*SUMPRODUCT($C$34:$C$35,T34:T35) -> 1.21002e+09 | V39: =$C39*SUMPRODUCT($C$34:$C$35,U34:U35) -> 1.21002e+09 | W39: =$C39*SUMPRODUCT($C$34:$C$35,V34:V35) -> 1.243185e+09 | X39: =$C39*SUMPRODUCT($C$34:$C$35,W34:W35) -> 1.48338e+09 | Y39: =$C39*SUMPRODUCT($C$34:$C$35,X34:X35) -> 1.48338e+09 | Z39: =$C39*SUMPRODUCT($C$34:$C$35,Y34:Y35) -> 1.490415e+09 | AA39: =$C39*SUMPRODUCT($C$34:$C$35,Z34:Z35) -> 1.53966e+09 | AB39: =$C39*SUMPRODUCT($C$34:$C$35,AA34:AA35) -> 1.53966e+09 | ... AE39: =$C39*SUMPRODUCT($C$34:$C$35,AD34:AD35) -> 2.80881e+09 | AG39: =$C39*SUMPRODUCT($C$34:$C$35,AE34:AE35) -> 2.54895e+09 | AH39: =$C39*SUMPRODUCT($C$34:$C$35,AG34:AG35) -> 2.240355e+09 | AI39: =$C39*SUMPRODUCT($C$34:$C$35,AH34:AH35) -> 2.207955e+09 | AJ39: =$C39*SUMPRODUCT($C$34:$C$35,AI34:AI35) -> 2.290845e+09 | AK39: =$C39*SUMPRODUCT($C$34:$C$35,AJ34:AJ35) -> 2.899335e+09 | AL39: =$C39*SUMPRODUCT($C$34:$C$35,AK34:AK35) -> 2.899335e+09 | AM39: =$C39*SUMPRODUCT($C$34:$C$35,AL34:AL35) -> 2.915085e+09 | AN39: =$C39*SUMPRODUCT($C$34:$C$35,AM34:AM35) -> 3.04455e+09 | AO39: =$C39*SUMPRODUCT($C$34:$C$35,AN34:AN35) -> 3.05751e+09 | ... AT39: =$C39*SUMPRODUCT($C$34:$C$35,AS34:AS35) -> 0
A40: TOTAL PAYMENT | G40: =SUM(G38:G39) -> 0 | H40: =SUM(H38:H39) -> 0 | I40: =SUM(I38:I39) -> 0 | J40: =SUM(J38:J39) -> 0 | K40: =SUM(K38:K39) -> 642530000 | L40: =SUM(L38:L39) -> 3089370000 | M40: =SUM(M38:M39) -> 4064555000 | N40: =SUM(N38:N39) -> 4390845000 | ... AE40: =SUM(AE38:AE39) -> 8756360000 | AG40: =SUM(AG38:AG39) -> 7776445000 | AH40: =SUM(AH38:AH39) -> 7392250000 | AI40: =SUM(AI38:AI39) -> 7553260000 | AJ40: =SUM(AJ38:AJ39) -> 9055960000 | AK40: =SUM(AK38:AK39) -> 9664450000 | AL40: =SUM(AL38:AL39) -> 9701200000 | AM40: =SUM(AM38:AM39) -> 10019035000 | AN40: =SUM(AN38:AN39) -> 10178740000 | ... AT40: =SUM(AT38:AT39) -> 0
A41: Payable (Offseting)
A42: For following period | F42: =G39 -> 0 | G42: =H39 -> 0 | H42: =I39 -> 0 | I42: =J39 -> 0 | J42: =K39 -> 0 | K42: =L39 -> 2.7537e+08 | L42: =M39 -> 1.206e+09 | M42: =N39 -> 1.225095e+09 | ... Q42: =R39 -> 1.422075e+09 | R42: =T39 -> 1.395945e+09 | S42: =IF(ISBLANK(S32),R42) -> 1.395945e+09 | T42: =U39 -> 1.21002e+09 | U42: =V39 -> 1.21002e+09 | V42: =W39 -> 1.243185e+09 | W42: =X39 -> 1.48338e+09 | X42: =Y39 -> 1.48338e+09 | Y42: =Z39 -> 1.490415e+09 | Z42: =AA39 -> 1.53966e+09 | AA42: =AB39 -> 1.53966e+09 | ... AD42: =AE39 -> 2.80881e+09 | AE42: =AG39 -> 2.54895e+09 | AF42: =IF(ISBLANK(AF32),AE42) -> 2.54895e+09 | AG42: =AH39 -> 2.240355e+09 | AH42: =AI39 -> 2.207955e+09 | AI42: =AJ39 -> 2.290845e+09 | AJ42: =AK39 -> 2.899335e+09 | AK42: =AL39 -> 2.899335e+09 | AL42: =AM39 -> 2.915085e+09 | AM42: =AN39 -> 3.04455e+09 | AN42: =AO39 -> 3.05751e+09 | ... AS42: =AT39 -> 0 | AT42: =BA39 -> 0
A43: ACCOUNT PAYABLE | G43: =G42-G39+F45 -> 0 | H43: =H42-H39+G43 -> 0 | I43: =I42-I39+H43 -> 0 | J43: =J42-J39+I43 -> 0 | K43: =K42-K39+J43 -> 2.7537e+08 | L43: =L42-L39+K43 -> 1.206e+09 | M43: =M42-M39+L43 -> 1.225095e+09 | N43: =N42-N39+M43 -> 1.35675e+09 | O43: =O42-O39+N43 -> 1.36479e+09 | ... R43: =R42-R39+Q43 -> 1.395945e+09 | T43: =T42-T39+R43 -> 1.21002e+09 | U43: =U42-U39+T43 -> 1.21002e+09 | V43: =V42-V39+U43 -> 1.243185e+09 | W43: =W42-W39+V43 -> 1.48338e+09 | X43: =X42-X39+W43 -> 1.48338e+09 | Y43: =Y42-Y39+X43 -> 1.490415e+09 | Z43: =Z42-Z39+Y43 -> 1.53966e+09 | AA43: =AA42-AA39+Z43 -> 1.53966e+09 | AB43: =AB42-AB39+AA43 -> 1.546695e+09 | ... AE43: =AE42-AE39+AD43 -> 2.54895e+09 | AG43: =AG42-AG39+AE43 -> 2.240355e+09 | AH43: =AH42-AH39+AG43 -> 2.207955e+09 | AI43: =AI42-AI39+AH43 -> 2.290845e+09 | AJ43: =AJ42-AJ39+AI43 -> 2.899335e+09 | AK43: =AK42-AK39+AJ43 -> 2.899335e+09 | AL43: =AL42-AL39+AK43 -> 2.915085e+09 | AM43: =AM42-AM39+AL43 -> 3.04455e+09 | AN43: =AN42-AN39+AM43 -> 3.05751e+09 | AO43: =AO42-AO39+AN43 -> 3.1518e+09 | ... AT43: =AT42-AT39+AS43 -> 0

Sheet Marketing plan
A1: Marketing | E1: 2025 | R1: 2026 | AJ1: 2027
E2: Q1 | H2: Q2 | K2: Q3 | N2: Q4 | R2: Q1 | U2: Q2 | AA2: Q3 | AD2: Q4 | AJ2: Q1 | AM2: Q2 | AS2: Q3 | AV2: Q4
E3: 1 | F3: 2 | G3: 3 | H3: 4 | I3: 5 | J3: 6 | K3: 7 | L3: 8 | M3: 9 | N3: 10 | O3: 11 | P3: 12 | R3: 1 | S3: 2 | T3: 3 | U3: 4/H1 | V3: 4/H2 | W3: 5/H1 | X3: 5/H2 | Y3: 6/H1 | Z3: 6/H2 | AA3: 7 | AB3: 8 | AC3: 9 | AD3: 10/1H | AE3: 10/2H | AF3: 11/1H | AG3: 11/2H | AH3: 12/1H | AI3: 12/2H | AJ3: 1 | AK3: 2 | AL3: 3 | AM3: 4/H1 | AN3: 4/H2 | AO3: 5/H1 | AP3: 5/H2 | AQ3: 6/H1 | AR3: 6/H2 | AS3: 7 | AT3: 8 | AU3: 9 | AV3: 10/1H | AW3: 10/2H | AX3: 11/1H | AY3: 11/2H | AZ3: 12/1H | BA3: 12/2H
A4: Advertising | E4: =SUM(E5:E10) -> 0 | F4: =SUM(F5:F10) -> 0 | G4: =SUM(G5:G10) -> 0 | H4: =SUM(H5:H10) -> 0 | I4: =SUM(I5:I10) -> 11000000 | J4: =SUM(J5:J10) -> 20000000 | K4: =SUM(K5:K10) -> 8500000 | L4: =SUM(L5:L10) -> 22000000 | ... P4: =SUM(P5:P10) -> 8500000 | R4: =SUM(R5:R10) -> 6500000 | S4: =SUM(S5:S10) -> 6500000 | T4: =SUM(T5:T10) -> 7500000 | U4: =SUM(U5:U10) -> 3750000 | V4: =SUM(V5:V10) -> 3750000 | W4: =SUM(W5:W10) -> 5750000 | X4: =SUM(X5:X10) -> 5750000 | Y4: =SUM(Y5:Y10) -> 3750000 | ... BA4: =SUM(BA5:BA10) -> 4250000
A5: Print Ads | I5: 3000000 | J5: 3000000 | K5: =500000 -> 500000 | L5: 3000000 | M5: 500000 | N5: 500000 | O5: 500000 | P5: 500000 | R5: 500000 | S5: 500000 | T5: 500000 | U5: =500000/2 -> 250000 | V5: =500000/2 -> 250000 | W5: =500000/2 -> 250000 | X5: =500000/2 -> 250000 | Y5: =500000/2 -> 250000 | Z5: =500000/2 -> 250000 | AA5: 500000 | AB5: 500000 | AC5: 500000 | AD5: 250000 | AE5: 250000 | AF5: =3000000/2 -> 1500000 | AG5: =3000000/2 -> 1500000 | AH5: 250000 | AI5: 250000 | AJ5: 3000000 | AK5: 500000 | AL5: =500000 -> 500000 | AM5: 250000 | AN5: 250000 | AO5: 250000 | AP5: 250000 | AQ5: 250000 | AR5: 250000 | AS5: 500000 | AT5: 500000 | AU5: 500000 | AV5: 250000 | AW5: 250000 | AX5: 250000 | AY5: 250000 | AZ5: 250000 | BA5: 250000
A6: Banner Ads | I6: 3000000 | J6: 6000000 | K6: 3000000 | L6: 6000000 | M6: 3000000 | N6: 3000000 | O6: 3000000 | P6: 3000000 | R6: 3000000 | S6: 3000000 | T6: 3000000 | U6: =3000000/2 -> 1500000 | V6: =3000000/2 -> 1500000 | W6: =3000000/2 -> 1500000 | X6: =3000000/2 -> 1500000 | Y6: =3000000/2 -> 1500000 | Z6: =3000000/2 -> 1500000 | AA6: 3000000 | AB6: 3000000 | AC6: 3000000 | AD6: =3000000/2 -> 1500000 | AE6: =3000000/2 -> 1500000 | AF6: =6000000/2 -> 3000000 | AG6: =6000000/2 -> 3000000 | AH6: =3000000/2 -> 1500000 | AI6: =3000000/2 -> 1500000 | AJ6: 6000000 | AK6: 3000000 | AL6: 3000000 | AM6: =3000000/2 -> 1500000 | AN6: =3000000/2 -> 1500000 | AO6: =3000000/2 -> 1500000 | AP6: =3000000/2 -> 1500000 | AQ6: =3000000/2 -> 1500000 | AR6: =3000000/2 -> 1500000 | AS6: 3000000 | AT6: 3000000 | AU6: 3000000 | AV6: =3000000/2 -> 1500000 | AW6: =3000000/2 -> 1500000 | AX6: =3000000/2 -> 1500000 | AY6: =3000000/2 -> 1500000 | AZ6: =3000000/2 -> 1500000 | BA6: =3000000/2 -> 1500000
A7: Public Relations | I7: 2000000 | J7: 3000000 | K7: 3000000 | L7: 5000000 | M7: 2000000 | N7: 2000000 | O7: 2000000 | P7: 2000000 | R7: 2000000 | S7: 2000000 | T7: 2000000 | U7: 1000000 | V7: 1000000 | W7: 1000000 | X7: 1000000 | Y7: 1000000 | Z7: 1000000 | AA7: 2000000 | AB7: 2000000 | AC7: 2000000 | AD7: 1000000 | AE7: 1000000 | AF7: =5000000/2 -> 2500000 | AG7: =5000000/2 -> 2500000 | AH7: 1000000 | AI7: 1000000 | AJ7: 5000000 | AK7: 2000000 | AL7: 2000000 | AM7: 1000000 | AN7: 1000000 | AO7: 1000000 | AP7: 1000000 | AQ7: 1000000 | AR7: 1000000 | AS7: 2000000 | AT7: 2000000 | AU7: 2000000 | AV7: 1000000 | AW7: 1000000 | AX7: 1000000 | AY7: 1000000 | AZ7: 1000000 | BA7: 1000000
A8: Press Releases | J8: 3000000 | L8: 3000000 | W8: =3000000/2 -> 1500000 | X8: =3000000/2 -> 1500000 | AF8: =3000000/2 -> 1500000 | AG8: =3000000/2 -> 1500000 | AH8: =3000000/2 -> 1500000 | AI8: =3000000/2 -> 1500000 | AJ8: 3000000
A9: Booths | I9: 3000000 | J9: 5000000 | K9: 2000000 | L9: 5000000 | M9: 2000000 | AF9: =10000000/2 -> 5000000 | AG9: =10000000/2 -> 5000000 | AJ9: 10000000
A10: Collaborations | N10: 2000000 | O10: 2000000 | P10: 3000000 | R10: 1000000 | S10: 1000000 | T10: 2000000 | U10: =2000000/2 -> 1000000 | V10: =2000000/2 -> 1000000 | W10: =3000000/2 -> 1500000 | X10: =3000000/2 -> 1500000 | Y10: =2000000/2 -> 1000000 | Z10: 1000000 | AA10: 1000000 | AB10: 2000000 | AC10: 2000000 | AD10: 1500000 | AE10: 1500000 | AF10: =5000000/2 -> 2500000 | AG10: =5000000/2 -> 2500000 | AH10: =3000000/2 -> 1500000 | AI10: =3000000/2 -> 1500000 | AJ10: 5000000 | AK10: 1000000 | AL10: 2000000 | AM10: 1000000 | AN10: 1000000 | AO10: =3000000/2 -> 1500000 | AP10: =3000000/2 -> 1500000 | AQ10: 1000000 | AR10: 1000000 | AS10: 1000000 | AT10: 2000000 | AU10: 1000000 | AV10: =1000000/2 -> 500000 | AW10: =1000000/2 -> 500000 | AX10: =1000000/2 -> 500000 | AY10: =1000000/2 -> 500000 | AZ10: =3000000/2 -> 1500000 | BA10: =3000000/2 -> 1500000
A11: Promotional Expenses | J11: =J16*(J17*J19+J18*J20)+J21+J22 -> 0 | K11: =K16*(K17*K19+K18*K20)+K21+K22 -> 0 | L11: =L16*(L17*L19+L18*L20)+L21+L22 -> 5000000 | M11: =M16*(M17*M19+M18*M20)+M21+M22 -> 5000000 | N11: =N16*(N17*N19+N18*N20)+N21+N22 -> 5000000 | O11: =O16*(O17*O19+O18*O20)+O21+O22 -> 5000000 | P11: =P16*(P17*P19+P18*P20)+P21+P22 -> 5000000 | R11: =R16*(R17*R19+R18*R20)+R21+R22 -> 86751600 | S11: =S16*(S17*S19+S18*S20)+S21+S22 -> 86751600 | T11: =T16*(T17*T19+T18*T20)+T21+T22 -> 86751600 | U11: =U16*(U17*U19+U18*U20)+U21+U22 -> 3750000 | V11: =V16*(V17*V19+V18*V20)+V21+V22 -> 3750000 | W11: =W16*(W17*W19+W18*W20)+W21+W22 -> 103970400 | X11: =X16*(X17*X19+X18*X20)+X21+X22 -> 103970400 | Y11: =Y16*(Y17*Y19+Y18*Y20)+Y21+Y22 -> 2500000 | ... BA11: =BA16*(BA17*BA19+BA18*BA20)+BA21+BA22 -> 2500000
A12: Promotion for new customers | B12: % | W12: 0.02 | X12: 0.02 | AE12: 0.02 | AF12: 0.02 | AG12: 0.02 | AO12: 0.02 | AP12: 0.02 | AW12: 0.02 | AX12: 0.02 | AY12: 0.02
A13: Flash sales | B13: %
A14: Eco-Ride New Year Sale | B14: % | R14: 0.01 | S14: 0.01 | T14: 0.01 | AJ14: 0.01 | AK14: 0.01 | AL14: 0.01
A15: Fall Sales | B15: % | AA15: 0.01 | AB15: 0.01 | AC15: 0.01 | AS15: 0.01 | AT15: 0.01 | AU15: 0.01
A16: Sum % | B16: % | J16: =SUM(J12:J15) -> 0 | K16: =SUM(K12:K15) -> 0 | L16: =SUM(L12:L15) -> 0 | M16: =SUM(M12:M15) -> 0 | N16: =SUM(N12:N15) -> 0 | O16: =SUM(O12:O15) -> 0 | P16: =SUM(P12:P15) -> 0 | R16: =SUM(R12:R15) -> 0.01 | S16: =SUM(S12:S15) -> 0.01 | T16: =SUM(T12:T15) -> 0.01 | U16: =SUM(U12:U15) -> 0 | V16: =SUM(V12:V15) -> 0 | W16: =SUM(W12:W15) -> 0.02 | X16: =SUM(X12:X15) -> 0.02 | Y16: =SUM(Y12:Y15) -> 0 | ... BA16: =SUM(BA12:BA15) -> 0
A17: Selling price | C17: Standard | J17: ='Operations plan'!$C$28 -> 6790000 | K17: ='Operations plan'!$C$28 -> 6790000 | L17: ='Operations plan'!$C$28 -> 6790000 | M17: ='Operations plan'!$C$28 -> 6790000 | N17: ='Operations plan'!$C$28 -> 6790000 | O17: ='Operations plan'!$C$28 -> 6790000 | P17: ='Operations plan'!$C$28 -> 6790000 | R17: ='Operations plan'!$C$28 -> 6790000 | S17: ='Operations plan'!$C$28 -> 6790000 | T17: ='Operations plan'!$C$28 -> 6790000 | U17: ='Operations plan'!$C$28 -> 6790000 | V17: ='Operations plan'!$C$28 -> 6790000 | W17: ='Operations plan'!$C$28 -> 6790000 | X17: ='Operations plan'!$C$28 -> 6790000 | Y17: ='Operations plan'!$C$28 -> 6790000 | ... BA17: ='Operations plan'!$C$28 -> 6790000
C18: E-Bike | J18: ='Operations plan'!$C$29 -> 17990000 | K18: ='Operations plan'!$C$29 -> 17990000 | L18: ='Operations plan'!$C$29 -> 17990000 | M18: ='Operations plan'!$C$29 -> 17990000 | N18: ='Operations plan'!$C$29 -> 17990000 | O18: ='Operations plan'!$C$29 -> 17990000 | P18: ='Operations plan'!$C$29 -> 17990000 | R18: ='Operations plan'!$C$29 -> 17990000 | S18: ='Operations plan'!$C$29 -> 17990000 | T18: ='Operations plan'!$C$29 -> 17990000 | U18: ='Operations plan'!$C$29 -> 17990000 | V18: ='Operations plan'!$C$29 -> 17990000 | W18: ='Operations plan'!$C$29 -> 17990000 | X18: ='Operations plan'!$C$29 -> 17990000 | Y18: ='Operations plan'!$C$29 -> 17990000 | ... BA18: ='Operations plan'!$C$29 -> 17990000
A19: Sale vol. | B19: product | C19: Standard | J19: ='Operations plan'!J7+'Operations plan'!J17 -> 1200 | K19: ='Operations plan'!K7+'Operations plan'!K17 -> 1200 | L19: ='Operations plan'!L7+'Operations plan'!L17 -> 1350 | M19: ='Operations plan'!M7+'Operations plan'!M17 -> 1350 | N19: ='Operations plan'!N7+'Operations plan'!N17 -> 1415 | O19: ='Operations plan'!O7+'Operations plan'!O17 -> 1415 | P19: ='Operations plan'!P7+'Operations plan'!P17 -> 1415 | R19: ='Operations plan'!R7+'Operations plan'!R17 -> 1204 | S19: ='Operations plan'!S7+'Operations plan'!S17 -> 1204 | T19: ='Operations plan'!T7+'Operations plan'!T17 -> 1204 | U19: =('Operations plan'!U7+'Operations plan'!U17)/2 -> 738 | V19: =('Operations plan'!U7+'Operations plan'!U17)/2 -> 738 | W19: =('Operations plan'!V7+'Operations plan'!V17)/2 -> 738 | X19: =('Operations plan'!V7+'Operations plan'!V17)/2 -> 738 | Y19: =('Operations plan'!W7+'Operations plan'!W17)/2 -> 738 | Z19: =('Operations plan'!W7+'Operations plan'!W17)/2 -> 738 | AA19: ='Operations plan'!X7+'Operations plan'!X17 -> 1532 | AB19: ='Operations plan'!Y7+'Operations plan'!Y17 -> 1532 | AC19: ='Operations plan'!Z7+'Operations plan'!Z17 -> 1532 | AD19: =('Operations plan'!AA7+'Operations plan'!AA17)/2 -> 798.5 | AE19: =('Operations plan'!AA7+'Operations plan'!AA17)/2 -> 798.5 | AF19: =('Operations plan'!AB7+'Operations plan'!AB17)/2 -> 801 | AG19: =('Operations plan'!AB7+'Operations plan'!AB17)/2 -> 801 | AH19: =('Operations plan'!AC7+'Operations plan'!AC17)/2 -> 803.5 | AI19: =('Operations plan'!AC7+'Operations plan'!AC17)/2 -> 803.5 | AJ19: ='Operations plan'!AE7+'Operations plan'!AE17 -> 1391 | AK19: ='Operations plan'!AF7+'Operations plan'!AF17 -> 1391 | AL19: ='Operations plan'!AG7+'Operations plan'!AG17 -> 1391 | AM19: ='Operations plan'!AH7+'Operations plan'!AH17 -> 1547 | AN19: =AM19 -> 1547 | AO19: ='Operations plan'!AI7+'Operations plan'!AI17 -> 1547 | AP19: =AO19 -> 1547 | AQ19: =('Operations plan'!AJ7+'Operations plan'!AJ17)/2 -> 773.5 | AR19: =AQ19 -> 773.5 | AS19: ='Operations plan'!AK7+'Operations plan'!AK17 -> 1598 | AT19: ='Operations plan'!AL7+'Operations plan'!AL17 -> 1598 | AU19: ='Operations plan'!AM7+'Operations plan'!AM17 -> 1598 | AV19: =('Operations plan'!AN7+'Operations plan'!AN17)/2 -> 838 | AW19: =AV19 -> 838 | AX19: =('Operations plan'!AO7+'Operations plan'!AO17)/2 -> 840.5 | AY19: =AX19 -> 840.5 | AZ19: =('Operations plan'!AP7+'Operations plan'!AP17)/2 -> 843 | BA19: =AZ19 -> 843
B20: product | C20: E-Bike | J20: ='Operations plan'!J8+'Operations plan'!J18 -> 0 | K20: ='Operations plan'!K8+'Operations plan'!K18 -> 0 | L20: ='Operations plan'!L8+'Operations plan'!L18 -> 0 | M20: ='Operations plan'!M8+'Operations plan'!M18 -> 0 | N20: ='Operations plan'!N8+'Operations plan'!N18 -> 0 | O20: ='Operations plan'!O8+'Operations plan'!O18 -> 0 | P20: ='Operations plan'!P8+'Operations plan'!P18 -> 0 | R20: ='Operations plan'!R8+'Operations plan'!R18 -> 0 | S20: ='Operations plan'!S8+'Operations plan'!S18 -> 0 | T20: ='Operations plan'!T8+'Operations plan'!T18 -> 0 | U20: =('Operations plan'!U8+'Operations plan'!U18)/2 -> 0 | V20: =('Operations plan'!U8+'Operations plan'!U18)/2 -> 0 | W20: =('Operations plan'!V8+'Operations plan'!V18)/2 -> 0 | X20: =('Operations plan'!V8+'Operations plan'!V18)/2 -> 0 | Y20: =('Operations plan'!W8+'Operations plan'!W18)/2 -> 0 | Z20: =('Operations plan'!W8+'Operations plan'!W18)/2 -> 0 | AA20: ='Operations plan'!X8+'Operations plan'!X18 -> 0 | AB20: ='Operations plan'!Y8+'Operations plan'!Y18 -> 0 | AC20: ='Operations plan'!Z8+'Operations plan'!Z18 -> 0 | AD20: =('Operations plan'!AA8+'Operations plan'!AA18)/2 -> 0 | AE20: =('Operations plan'!AA8+'Operations plan'!AA18)/2 -> 0 | AF20: =('Operations plan'!AB8+'Operations plan'!AB18)/2 -> 150 | AG20: =('Operations plan'!AB8+'Operations plan'!AB18)/2 -> 150 | AH20: =('Operations plan'!AC8+'Operations plan'!AC18)/2 -> 150 | AI20: =('Operations plan'!AC8+'Operations plan'!AC18)/2 -> 150 | AJ20: ='Operations plan'!AE8+'Operations plan'!AE18 -> 260 | AK20: ='Operations plan'!AF8+'Operations plan'!AF18 -> 250 | AL20: ='Operations plan'!AG8+'Operations plan'!AG18 -> 250 | AM20: ='Operations plan'!AH8+'Operations plan'!AH18 -> 415 | AN20: =AM20 -> 415 | AO20: ='Operations plan'!AI8+'Operations plan'!AI18 -> 415 | AP20: =AO20 -> 415 | AQ20: =('Operations plan'!AJ8+'Operations plan'!AJ18)/2 -> 207.5 | AR20: =AQ20 -> 207.5 | AS20: ='Operations plan'!AK8+'Operations plan'!AK18 -> 444 | AT20: ='Operations plan'!AL8+'Operations plan'!AL18 -> 444 | AU20: ='Operations plan'!AM8+'Operations plan'!AM18 -> 474 | AV20: =('Operations plan'!AN8+'Operations plan'!AN18)/2 -> 238.5 | AW20: =AV20 -> 238.5 | AX20: =('Operations plan'!AO8+'Operations plan'!AO18)/2 -> 240 | AY20: =AX20 -> 240 | AZ20: =('Operations plan'!AP8+'Operations plan'!AP18)/2 -> 241.5 | BA20: =AZ20 -> 241.5
A21: In-app promotions | U21: =5000000/4 -> 1250000 | V21: =5000000/4 -> 1250000 | W21: =5000000/4 -> 1250000 | X21: =5000000/4 -> 1250000
A22: Loyalty membership discounts | L22: 5000000 | M22: 5000000 | N22: 5000000 | O22: 5000000 | P22: 5000000 | R22: 5000000 | S22: 5000000 | T22: 5000000 | U22: =5000000/2 -> 2500000 | V22: =5000000/2 -> 2500000 | W22: =5000000/2 -> 2500000 | X22: =5000000/2 -> 2500000 | Y22: =5000000/2 -> 2500000 | Z22: =5000000/2 -> 2500000 | AA22: 5000000 | AB22: 5000000 | AC22: 5000000 | AD22: =5000000/2 -> 2500000 | AE22: =5000000/2 -> 2500000 | AF22: =5000000/2 -> 2500000 | AG22: =5000000/2 -> 2500000 | AH22: =5000000/2 -> 2500000 | AI22: =5000000/2 -> 2500000 | AJ22: 5000000 | AK22: 5000000 | AL22: 5000000 | AM22: =5000000/2 -> 2500000 | AN22: =5000000/2 -> 2500000 | AO22: =5000000/2 -> 2500000 | AP22: =5000000/2 -> 2500000 | AQ22: =5000000/2 -> 2500000 | AR22: =5000000/2 -> 2500000 | AS22: 5000000 | AT22: 5000000 | AU22: 5000000 | AV22: =5000000/2 -> 2500000 | AW22: =5000000/2 -> 2500000 | AX22: =5000000/2 -> 2500000 | AY22: =5000000/2 -> 2500000 | AZ22: =5000000/2 -> 2500000 | BA22: =5000000/2 -> 2500000
A23: Digital Marketing | E23: =SUM(E24:E28) -> 61250000 | F23: =SUM(F24:F28) -> 61250000 | G23: =SUM(G24:G28) -> 61250000 | H23: =SUM(H24:H28) -> 58750000 | I23: =SUM(I24:I28) -> 58750000 | J23: =SUM(J24:J28) -> 58750000 | K23: =SUM(K24:K28) -> 58750000 | L23: =SUM(L24:L28) -> 133750000 | ... P23: =SUM(P24:P28) -> 123750000 | R23: =SUM(R24:R28) -> 56750000 | S23: =SUM(S24:S28) -> 56750000 | T23: =SUM(T24:T28) -> 56750000 | U23: =SUM(U24:U28) -> 21125000 | V23: =SUM(V24:V28) -> 21125000 | W23: =SUM(W24:W28) -> 33000000 | X23: =SUM(X24:X28) -> 33000000 | Y23: =SUM(Y24:Y28) -> 33000000 | ... BA23: =SUM(BA24:BA28) -> 80500000
A24: Digital Ads | E24: 30000000 | F24: 30000000 | G24: 30000000 | H24: 30000000 | I24: 30000000 | J24: 30000000 | K24: 30000000 | L24: 100000000 | M24: 30000000 | N24: 30000000 | O24: 100000000 | P24: 100000000 | R24: 30000000 | S24: 30000000 | T24: 30000000 | AA24: 30000000 | AB24: 30000000 | AC24: 30000000 | AD24: 30000000 | AE24: =100000000/2 -> 50000000 | AF24: =100000000/2 -> 50000000 | AG24: =100000000/2 -> 50000000 | AH24: =100000000/2 -> 50000000 | AI24: =100000000/2 -> 50000000 | AJ24: 30000000 | AK24: 30000000 | AL24: 30000000 | AM24: =100000000/2 -> 50000000 | AN24: =100000000/2 -> 50000000 | AO24: =100000000/2 -> 50000000 | AP24: =100000000/2 -> 50000000 | AQ24: =100000000/2 -> 50000000 | AR24: =100000000/2 -> 50000000 | AS24: 30000000 | AT24: 30000000 | AU24: 30000000 | AV24: =100000000/2 -> 50000000 | AW24: =100000000/2 -> 50000000 | AX24: =100000000/2 -> 50000000 | AY24: =100000000/2 -> 50000000 | AZ24: =100000000/2 -> 50000000 | BA24: =100000000/2 -> 50000000
A25: Website | E25: 15000000 | F25: 15000000 | G25: 15000000 | H25: 12500000 | I25: 12500000 | J25: 12500000 | K25: 12500000 | L25: 12500000 | M25: 12500000 | N25: 12500000 | O25: 12500000 | P25: 12500000 | R25: 12500000 | S25: 12500000 | T25: 12500000 | U25: =25000000/2 -> 12500000 | V25: 12500000 | W25: 12500000 | X25: 12500000 | Y25: 12500000 | Z25: 12500000 | AA25: 12500000 | AB25: 12500000 | AC25: 12500000 | AD25: =25000000/2 -> 12500000 | AE25: 12500000 | AF25: 12500000 | AG25: 12500000 | AH25: 12500000 | AI25: 12500000 | AJ25: 12500000 | AK25: 12500000 | AL25: 12500000 | AM25: =25000000/2 -> 12500000 | AN25: 12500000 | AO25: 12500000 | AP25: 12500000 | AQ25: 12500000 | AR25: 12500000 | AS25: 12500000 | AT25: 12500000 | AU25: 12500000 | AV25: =25000000/2 -> 12500000 | AW25: 12500000 | AX25: 12500000 | AY25: 12500000 | AZ25: 12500000 | BA25: 12500000
A26: Email Marketing | E26: 5000000 | F26: 5000000 | G26: 5000000 | H26: 5000000 | I26: 5000000 | J26: 5000000 | K26: =J26 -> 5000000 | L26: 10000000 | M26: 5000000 | R26: 3000000 | S26: 3000000 | T26: 3000000 | U26: 3000000 | V26: 3000000 | W26: 3000000 | X26: 3000000 | Y26: 3000000 | Z26: 3000000 | AA26: 3000000 | AB26: 3000000 | AC26: 3000000 | AD26: 3000000 | AE26: 3000000 | AF26: 3000000 | AG26: 3000000 | AH26: 3000000 | AI26: 3000000 | AJ26: 3000000 | AK26: 3000000 | AL26: 3000000 | AM26: 3000000 | AN26: 3000000 | AO26: 3000000 | AP26: 3000000 | AQ26: 3000000 | AR26: 3000000 | AS26: 3000000 | AT26: 3000000 | AU26: 3000000 | AV26: 3000000 | AW26: 3000000 | AX26: 3000000 | AY26: 3000000 | AZ26: 3000000 | BA26: 3000000
A27: SEO | E27: 5000000 | F27: 5000000 | G27: 5000000 | H27: 5000000 | I27: 5000000 | J27: 5000000 | K27: 5000000 | L27: 5000000 | M27: 5000000 | N27: 5000000 | O27: 5000000 | P27: 5000000 | R27: 5000000 | S27: 5000000 | T27: 5000000 | U27: =5000000/2 -> 2500000 | V27: =5000000/2 -> 2500000 | W27: =5000000/2 -> 2500000 | X27: =5000000/2 -> 2500000 | Y27: =5000000/2 -> 2500000 | Z27: =5000000/2 -> 2500000 | AA27: 5000000 | AB27: 5000000 | AC27: 5000000 | AD27: =5000000/2 -> 2500000 | AE27: =5000000/2 -> 2500000 | AF27: =5000000/2 -> 2500000 | AG27: =5000000/2 -> 2500000 | AH27: =5000000/2 -> 2500000 | AI27: =5000000/2 -> 2500000 | AJ27: 5000000 | AK27: 5000000 | AL27: 5000000 | AM27: =5000000/2 -> 2500000 | AN27: =5000000/2 -> 2500000 | AO27: =5000000/2 -> 2500000 | AP27: =5000000/2 -> 2500000 | AQ27: =5000000/2 -> 2500000 | AR27: =5000000/2 -> 2500000 | AS27: 5000000 | AT27: 5000000 | AU27: 5000000 | AV27: =5000000/2 -> 2500000 | AW27: =5000000/2 -> 2500000 | AX27: =5000000/2 -> 2500000 | AY27: =5000000/2 -> 2500000 | AZ27: =5000000/2 -> 2500000 | BA27: =5000000/2 -> 2500000
A28: App Development | E28: =100000000/16 -> 6250000 | F28: =E28 -> 6250000 | G28: =E28 -> 6250000 | H28: =G28 -> 6250000 | I28: =H28 -> 6250000 | J28: =I28 -> 6250000 | K28: =J28 -> 6250000 | L28: =K28 -> 6250000 | M28: =L28 -> 6250000 | N28: =M28 -> 6250000 | O28: =N28 -> 6250000 | P28: =O28 -> 6250000 | R28: =P28 -> 6250000 | S28: =R28 -> 6250000 | T28: =S28 -> 6250000 | U28: =T28/2 -> 3125000 | V28: =U28 -> 3125000 | W28: =30000000/2 -> 15000000 | X28: =W28 -> 15000000 | Y28: =X28 -> 15000000 | Z28: =Y28 -> 15000000 | AA28: 25000000 | AB28: 25000000 | AC28: 25000000 | AD28: =25000000/2 -> 12500000 | AE28: =25000000/2 -> 12500000 | AF28: =25000000/2 -> 12500000 | AG28: =25000000/2 -> 12500000 | AH28: =25000000/2 -> 12500000 | AI28: =25000000/2 -> 12500000 | AJ28: 25000000 | AK28: 25000000 | AL28: 25000000 | AM28: =25000000/2 -> 12500000 | AN28: =25000000/2 -> 12500000 | AO28: =25000000/2 -> 12500000 | AP28: =25000000/2 -> 12500000 | AQ28: =25000000/2 -> 12500000 | AR28: =25000000/2 -> 12500000 | AS28: 25000000 | AT28: 25000000 | AU28: 25000000 | AV28: =25000000/2 -> 12500000 | AW28: =25000000/2 -> 12500000 | AX28: =25000000/2 -> 12500000 | AY28: =25000000/2 -> 12500000 | AZ28: =25000000/2 -> 12500000 | BA28: =25000000/2 -> 12500000
A29: Viral video | H29: 30000000 | I29: 30000000 | J29: 30000000
